<robot name="robot">
    <link name="base_footprint"></link>
    <joint name="base_joint" type="fixed">
        <parent link="base_footprint" />
        <child link="base_link" />
        <origin xyz="0 0 0.04430988801299607" rpy="0 0 0" />
    </joint>
    <link name="base_link">
        <collision>
            <origin xyz="0 0 0" rpy="0 0 0" />
            <geometry>
                <box size="0.18 0.51 0.01" />
            </geometry>
        </collision>
        <collision>
            <origin xyz="0.09 0 0.11" rpy="0 0 0" />
            <geometry>
                <box size="0.01 0.51 0.22" />
            </geometry>
        </collision>
        <collision>
            <origin xyz="-0.09 0 0.11" rpy="0 0 0" />
            <geometry>
                <box size="0.01 0.51 0.22" />
            </geometry>
        </collision>
        <collision>
            <origin xyz="0 0 0.22" rpy="0 0 0" />
            <geometry>
                <box size="0.18 0.51 0.01" />
            </geometry>
        </collision>
        <inertial>
            <origin xyz="0 0 0.44" rpy="0 0 0" />
            <mass value="1" />
            <inertia ixx="0.16666666666666666" ixy="0" ixz="0" iyy="0.16666666666666666" iyz="0"
                izz="0.16666666666666666" />
        </inertial>
    </link>
    <joint name="base_link_to_cube1" type="revolute">
        <parent link="base_link" />
        <child link="cube1" />
        <origin xyz="0 0.26 0" rpy="0 1.5707963267948966 0" />
        <axis xyz="0 0 1" />
        <limit effort="1000.0" lower="-1" upper="1" velocity="0.5" />
    </joint>
    <link name="cube1">
        <collision>
            <origin xyz="-0.11 0 0" rpy="0 0 0" />
            <geometry>
                <box size="0.22 0.01 0.18" />
            </geometry>
        </collision>
        <collision>
            <origin xyz="-0.22 0.015 0" rpy="0 0 1.5707963267948963" />
            <geometry>
                <box size="0.03 0.003 0.03" />
            </geometry>
        </collision>
        <collision>
            <origin xyz="-0.195 0.03 0" rpy="0 0 0" />
            <geometry>
                <box size="0.05 0.003 0.03" />
            </geometry>
        </collision>
        <inertial>
            <origin xyz="-0.12 0.0 0" rpy="0 0 0" />
            <mass value="1" />
            <inertia ixx="0.016666666666666666" ixy="0" ixz="0" iyy="0.016666666666666666" iyz="0"
                izz="0.016666666666666666" />
        </inertial>
    </link>
</robot>